<?xml version="1.0" ?>
<robot name="a1_description" xmlns:xacro="http://www.ros.org/wiki/xacro">
  <material name="black">
    <color rgba="0.0 0.0 0.0 1.0"/>
  </material>
  <material name="blue">
    <color rgba="0.0 0.0 0.8 1.0"/>
  </material>
  <material name="green">
    <color rgba="0.0 0.8 0.0 1.0"/>
  </material>
  <material name="grey">
    <color rgba="0.2 0.2 0.2 1.0"/>
  </material>
  <material name="silver">
    <color rgba="0.913725490196 0.913725490196 0.847058823529 1.0"/>
  </material>
  <material name="orange">
    <!-- <color rgba="1.0 0.423529411765 0.0392156862745 1.0"/> -->
    <color rgba="0.12 0.15 0.2 1.0"/>
  </material>
  <material name="brown">
    <color rgba="0.870588235294 0.811764705882 0.764705882353 1.0"/>
  </material>
  <material name="red">
    <color rgba="0.8 0.0 0.0 1.0"/>
  </material>
  <material name="white">
    <color rgba="1.0 1.0 1.0 1.0"/>
  </material>
  <link name="base">
    <visual>
      <origin rpy="0 0 0" xyz="0 0 0"/>
      <geometry>
        <box size="0.001 0.001 0.001"/>
      </geometry>
    </visual>
  </link>
  <joint name="floating_base" type="fixed">
    <origin rpy="0 0 0" xyz="0 0 0"/>
    <parent link="base"/>
    <child link="trunk"/>
  </joint>
  <link name="trunk">
    <visual>
      <origin rpy="0 0 0" xyz="0 0 0"/>
      <geometry>
        <mesh filename="../meshes/trunk.dae" scale="1 1 1"/>
      </geometry>
      <material name="orange"/>
    </visual>
    <collision>
      <origin rpy="0 0 0" xyz="0 0 0"/>
      <geometry>
        <box size="0.267 0.194 0.114"/>
      </geometry>
    </collision>
    <inertial>
      <origin rpy="0 0 0" xyz="0.012731 0.002186 0.000515"/>
      <mass value="4.713"/>
      <inertia ixx="0.01683993" ixy="8.3902e-05" ixz="0.000597679" iyy="0.056579028" iyz="2.5134e-05" izz="0.064713601"/>
    </inertial>
  </link>
  <joint name="imu_joint" type="fixed">
    <parent link="trunk"/>
    <child link="imu_link"/>
    <origin rpy="0 0 0" xyz="0 0 0"/>
  </joint>
  <link name="imu_link">
    <inertial>
      <mass value="0.001"/>
      <origin rpy="0 0 0" xyz="0 0 0"/>
      <inertia ixx="0.0001" ixy="0" ixz="0" iyy="0.0001" iyz="0" izz="0.0001"/>
    </inertial>
    <visual>
      <origin rpy="0 0 0" xyz="0 0 0"/>
      <geometry>
        <box size="0.001 0.001 0.001"/>
      </geometry>
      <material name="red"/>
    </visual>
    <!-- <collision>
      <origin rpy="0 0 0" xyz="0 0 0"/>
      <geometry>
        <box size=".001 .001 .001"/>
      </geometry>
    </collision> -->
  </link>
  <joint name="FR_hip_joint" type="revolute">
    <origin rpy="0 0 0" xyz="0.183 -0.047 0"/>
    <parent link="trunk"/>
    <child link="FR_hip"/>
    <axis xyz="1 0 0"/>
    <dynamics damping="0" friction="0"/>
    <limit effort="20" lower="-0.802851455917" upper="0.802851455917" velocity="52.4"/>
  </joint>
  <link name="FR_hip">
    <visual>
      <origin rpy="3.14159265359 0 0" xyz="0 0 0"/>
      <geometry>
        <mesh filename="../meshes/hip.dae" scale="1 1 1"/>
      </geometry>
      <material name="orange"/>
    </visual>
    <!-- <collision>
      <origin rpy="1.57079632679 0 0" xyz="0 0 0"/>
      <geometry>
        <cylinder length="0.04" radius="0.046"/>
      </geometry>
    </collision> -->
    <inertial>
      <origin rpy="0 0 0" xyz="-0.003311 -0.000635 3.1e-05"/>
      <mass value="0.696"/>
      <inertia ixx="0.000469246" ixy="9.409e-06" ixz="-3.42e-07" iyy="0.00080749" iyz="4.66e-07" izz="0.000552929"/>
    </inertial>
  </link>
  <joint name="FR_hip_fixed" type="fixed">
    <origin rpy="0 0 0" xyz="0 -0.081 0"/>
    <parent link="FR_hip"/>
    <child link="FR_thigh_shoulder"/>
  </joint>
  <!-- this link is only for collision -->
  <link name="FR_thigh_shoulder">
    <!-- <collision>
      <origin rpy="1.57079632679 0 0" xyz="0 0 0"/>
      <geometry>
        <cylinder length="0.032" radius="0.041"/>
      </geometry>
    </collision> -->
  </link>
  <joint name="FR_thigh_joint" type="revolute">
    <origin rpy="0 0 0" xyz="0 -0.08505 0"/>
    <parent link="FR_hip"/>
    <child link="FR_thigh"/>
    <axis xyz="0 1 0"/>
    <dynamics damping="0" friction="0"/>
    <limit effort="55" lower="-1.0471975512" upper="4.18879020479" velocity="28.6"/>
  </joint>
  <link name="FR_thigh">
    <visual>
      <origin rpy="0 0 0" xyz="0 0 0"/>
      <geometry>
        <mesh filename="../meshes/thigh_mirror.dae" scale="1 1 1"/>
      </geometry>
      <material name="orange"/>
    </visual>
    <collision>
      <origin rpy="0 1.57079632679 0" xyz="0 0 -0.1"/>
      <geometry>
        <box size="0.2 0.0245 0.034"/>
      </geometry>
    </collision>
    <inertial>
      <origin rpy="0 0 0" xyz="-0.003237 0.022327 -0.027326"/>
      <mass value="1.013"/>
      <inertia ixx="0.005529065" ixy="-4.825e-06" ixz="0.000343869" iyy="0.005139339" iyz="-2.2448e-05" izz="0.001367788"/>
    </inertial>
  </link>
  <joint name="FR_calf_joint" type="revolute">
    <origin rpy="0 0 0" xyz="0 0 -0.2"/>
    <parent link="FR_thigh"/>
    <child link="FR_calf"/>
    <axis xyz="0 1 0"/>
    <dynamics damping="0" friction="0"/>
    <limit effort="55" lower="-2.69653369433" upper="-0.916297857297" velocity="28.6"/>
  </joint>
  <link name="FR_calf">
    <visual>
      <origin rpy="0 0 0" xyz="0 0 0"/>
      <geometry>
        <mesh filename="../meshes/calf.dae" scale="1 1 1"/>
      </geometry>
      <material name="orange"/>
    </visual>
    <collision>
      <origin rpy="0 1.57079632679 0" xyz="0 0 -0.1"/>
      <geometry>
        <box size="0.2 0.016 0.016"/>
      </geometry>
    </collision>
    <inertial>
      <origin rpy="0 0 0" xyz="0.006435 0.0 -0.107388"/>
      <mass value="0.166"/>
      <inertia ixx="0.002997972" ixy="0.0" ixz="-0.000141163" iyy="0.003014022" iyz="0.0" izz="3.2426e-05"/>
    </inertial>
  </link>
  <joint name="FR_foot_fixed" type="fixed" dont_collapse="true">
    <origin rpy="0 0 0" xyz="0 0 -0.2"/>
    <parent link="FR_calf"/>
    <child link="FR_foot"/>
  </joint>
  <link name="FR_foot">
    <visual>
      <origin rpy="0 0 0" xyz="0 0 0"/>
      <geometry>
        <sphere radius="0.01"/>
      </geometry>
      <material name="orange"/>
    </visual>
    <collision>
      <origin rpy="0 0 0" xyz="0 0 0"/>
      <geometry>
        <sphere radius="0.02"/>
      </geometry>
    </collision>
    <inertial>
      <mass value="0.06"/>
      <inertia ixx="9.6e-06" ixy="0.0" ixz="0.0" iyy="9.6e-06" iyz="0.0" izz="9.6e-06"/>
    </inertial>
  </link>
  <joint name="FL_hip_joint" type="revolute">
    <origin rpy="0 0 0" xyz="0.183 0.047 0"/>
    <parent link="trunk"/>
    <child link="FL_hip"/>
    <axis xyz="1 0 0"/>
    <dynamics damping="0" friction="0"/>
    <limit effort="20" lower="-0.802851455917" upper="0.802851455917" velocity="52.4"/>
  </joint>
  <link name="FL_hip">
    <visual>
      <origin rpy="0 0 0" xyz="0 0 0"/>
      <geometry>
        <mesh filename="../meshes/hip.dae" scale="1 1 1"/>
      </geometry>
      <material name="orange"/>
    </visual>
    <!-- <collision>
      <origin rpy="1.57079632679 0 0" xyz="0 0 0"/>
      <geometry>
        <cylinder length="0.04" radius="0.046"/>
      </geometry>
    </collision> -->
    <inertial>
      <origin rpy="0 0 0" xyz="-0.003311 0.000635 3.1e-05"/>
      <mass value="0.696"/>
      <inertia ixx="0.000469246" ixy="-9.409e-06" ixz="-3.42e-07" iyy="0.00080749" iyz="-4.66e-07" izz="0.000552929"/>
    </inertial>
  </link>
  <joint name="FL_hip_fixed" type="fixed">
    <origin rpy="0 0 0" xyz="0 0.081 0"/>
    <parent link="FL_hip"/>
    <child link="FL_thigh_shoulder"/>
  </joint>
  <!-- this link is only for collision -->
  <link name="FL_thigh_shoulder">
    <!-- <collision>
      <origin rpy="1.57079632679 0 0" xyz="0 0 0"/>
      <geometry>
        <cylinder length="0.032" radius="0.041"/>
      </geometry>
    </collision> -->
  </link>
  <joint name="FL_thigh_joint" type="revolute">
    <origin rpy="0 0 0" xyz="0 0.08505 0"/>
    <parent link="FL_hip"/>
    <child link="FL_thigh"/>
    <axis xyz="0 1 0"/>
    <dynamics damping="0" friction="0"/>
    <limit effort="55" lower="-1.0471975512" upper="4.18879020479" velocity="28.6"/>
  </joint>
  <link name="FL_thigh">
    <visual>
      <origin rpy="0 0 0" xyz="0 0 0"/>
      <geometry>
        <mesh filename="../meshes/thigh.dae" scale="1 1 1"/>
      </geometry>
      <material name="orange"/>
    </visual>
    <collision>
      <origin rpy="0 1.57079632679 0" xyz="0 0 -0.1"/>
      <geometry>
        <box size="0.2 0.0245 0.034"/>
      </geometry>
    </collision>
    <inertial>
      <origin rpy="0 0 0" xyz="-0.003237 -0.022327 -0.027326"/>
      <mass value="1.013"/>
      <inertia ixx="0.005529065" ixy="4.825e-06" ixz="0.000343869" iyy="0.005139339" iyz="2.2448e-05" izz="0.001367788"/>
    </inertial>
  </link>
  <joint name="FL_calf_joint" type="revolute">
    <origin rpy="0 0 0" xyz="0 0 -0.2"/>
    <parent link="FL_thigh"/>
    <child link="FL_calf"/>
    <axis xyz="0 1 0"/>
    <dynamics damping="0" friction="0"/>
    <limit effort="55" lower="-2.69653369433" upper="-0.916297857297" velocity="28.6"/>
  </joint>
  <link name="FL_calf">
    <visual>
      <origin rpy="0 0 0" xyz="0 0 0"/>
      <geometry>
        <mesh filename="../meshes/calf.dae" scale="1 1 1"/>
      </geometry>
      <material name="orange"/>
    </visual>
    <collision>
      <origin rpy="0 1.57079632679 0" xyz="0 0 -0.1"/>
      <geometry>
        <box size="0.2 0.016 0.016"/>
      </geometry>
    </collision>
    <inertial>
      <origin rpy="0 0 0" xyz="0.006435 0.0 -0.107388"/>
      <mass value="0.166"/>
      <inertia ixx="0.002997972" ixy="0.0" ixz="-0.000141163" iyy="0.003014022" iyz="0.0" izz="3.2426e-05"/>
    </inertial>
  </link>
  <joint name="FL_foot_fixed" type="fixed" dont_collapse="true">
    <origin rpy="0 0 0" xyz="0 0 -0.2"/>
    <parent link="FL_calf"/>
    <child link="FL_foot"/>
  </joint>
  <link name="FL_foot">
    <visual>
      <origin rpy="0 0 0" xyz="0 0 0"/>
      <geometry>
        <sphere radius="0.01"/>
      </geometry>
      <material name="orange"/>
    </visual>
    <collision>
      <origin rpy="0 0 0" xyz="0 0 0"/>
      <geometry>
        <sphere radius="0.02"/>
      </geometry>
    </collision>
    <inertial>
      <mass value="0.06"/>
      <inertia ixx="9.6e-06" ixy="0.0" ixz="0.0" iyy="9.6e-06" iyz="0.0" izz="9.6e-06"/>
    </inertial>
  </link>
  <joint name="RR_hip_joint" type="revolute">
    <origin rpy="0 0 0" xyz="-0.183 -0.047 0"/>
    <parent link="trunk"/>
    <child link="RR_hip"/>
    <axis xyz="1 0 0"/>
    <dynamics damping="0" friction="0"/>
    <limit effort="20" lower="-0.802851455917" upper="0.802851455917" velocity="52.4"/>
  </joint>
  <link name="RR_hip">
    <visual>
      <origin rpy="3.14159265359 3.14159265359 0" xyz="0 0 0"/>
      <geometry>
        <mesh filename="../meshes/hip.dae" scale="1 1 1"/>
      </geometry>
      <material name="orange"/>
    </visual>
    <!-- <collision>
      <origin rpy="1.57079632679 0 0" xyz="0 0 0"/>
      <geometry>
        <cylinder length="0.04" radius="0.046"/>
      </geometry>
    </collision> -->
    <inertial>
      <origin rpy="0 0 0" xyz="0.003311 -0.000635 3.1e-05"/>
      <mass value="0.696"/>
      <inertia ixx="0.000469246" ixy="-9.409e-06" ixz="3.42e-07" iyy="0.00080749" iyz="4.66e-07" izz="0.000552929"/>
    </inertial>
  </link>
  <joint name="RR_hip_fixed" type="fixed">
    <origin rpy="0 0 0" xyz="0 -0.081 0"/>
    <parent link="RR_hip"/>
    <child link="RR_thigh_shoulder"/>
  </joint>
  <!-- this link is only for collision -->
  <link name="RR_thigh_shoulder">
    <!-- <collision>
      <origin rpy="1.57079632679 0 0" xyz="0 0 0"/>
      <geometry>
        <cylinder length="0.032" radius="0.041"/>
      </geometry>
    </collision> -->
  </link>
  <joint name="RR_thigh_joint" type="revolute">
    <origin rpy="0 0 0" xyz="0 -0.08505 0"/>
    <parent link="RR_hip"/>
    <child link="RR_thigh"/>
    <axis xyz="0 1 0"/>
    <dynamics damping="0" friction="0"/>
    <limit effort="55" lower="-1.0471975512" upper="4.18879020479" velocity="28.6"/>
  </joint>
  <link name="RR_thigh">
    <visual>
      <origin rpy="0 0 0" xyz="0 0 0"/>
      <geometry>
        <mesh filename="../meshes/thigh_mirror.dae" scale="1 1 1"/>
      </geometry>
      <material name="orange"/>
    </visual>
    <collision>
      <origin rpy="0 1.57079632679 0" xyz="0 0 -0.1"/>
      <geometry>
        <box size="0.2 0.0245 0.034"/>
      </geometry>
    </collision>
    <inertial>
      <origin rpy="0 0 0" xyz="-0.003237 0.022327 -0.027326"/>
      <mass value="1.013"/>
      <inertia ixx="0.005529065" ixy="-4.825e-06" ixz="0.000343869" iyy="0.005139339" iyz="-2.2448e-05" izz="0.001367788"/>
    </inertial>
  </link>
  <joint name="RR_calf_joint" type="revolute">
    <origin rpy="0 0 0" xyz="0 0 -0.2"/>
    <parent link="RR_thigh"/>
    <child link="RR_calf"/>
    <axis xyz="0 1 0"/>
    <dynamics damping="0" friction="0"/>
    <limit effort="55" lower="-2.69653369433" upper="-0.916297857297" velocity="28.6"/>
  </joint>
  <link name="RR_calf">
    <visual>
      <origin rpy="0 0 0" xyz="0 0 0"/>
      <geometry>
        <mesh filename="../meshes/calf.dae" scale="1 1 1"/>
      </geometry>
      <material name="orange"/>
    </visual>
    <collision>
      <origin rpy="0 1.57079632679 0" xyz="0 0 -0.1"/>
      <geometry>
        <box size="0.2 0.016 0.016"/>
      </geometry>
    </collision>
    <inertial>
      <origin rpy="0 0 0" xyz="0.006435 0.0 -0.107388"/>
      <mass value="0.166"/>
      <inertia ixx="0.002997972" ixy="0.0" ixz="-0.000141163" iyy="0.003014022" iyz="0.0" izz="3.2426e-05"/>
    </inertial>
  </link>
  <joint name="RR_foot_fixed" type="fixed" dont_collapse="true">
    <origin rpy="0 0 0" xyz="0 0 -0.2"/>
    <parent link="RR_calf"/>
    <child link="RR_foot"/>
  </joint>
  <link name="RR_foot">
    <visual>
      <origin rpy="0 0 0" xyz="0 0 0"/>
      <geometry>
        <sphere radius="0.01"/>
      </geometry>
      <material name="orange"/>
    </visual>
    <collision>
      <origin rpy="0 0 0" xyz="0 0 0"/>
      <geometry>
        <sphere radius="0.02"/>
      </geometry>
    </collision>
    <inertial>
      <mass value="0.06"/>
      <inertia ixx="9.6e-06" ixy="0.0" ixz="0.0" iyy="9.6e-06" iyz="0.0" izz="9.6e-06"/>
    </inertial>
  </link>
  <joint name="RL_hip_joint" type="revolute">
    <origin rpy="0 0 0" xyz="-0.183 0.047 0"/>
    <parent link="trunk"/>
    <child link="RL_hip"/>
    <axis xyz="1 0 0"/>
    <dynamics damping="0" friction="0"/>
    <limit effort="20" lower="-0.802851455917" upper="0.802851455917" velocity="52.4"/>
  </joint>
  <link name="RL_hip">
    <visual>
      <origin rpy="0 3.14159265359 0" xyz="0 0 0"/>
      <geometry>
        <mesh filename="../meshes/hip.dae" scale="1 1 1"/>
      </geometry>
      <material name="orange"/>
    </visual>
    <!-- <collision>
      <origin rpy="1.57079632679 0 0" xyz="0 0 0"/>
      <geometry>
        <cylinder length="0.04" radius="0.046"/>
      </geometry>
    </collision> -->
    <inertial>
      <origin rpy="0 0 0" xyz="0.003311 0.000635 3.1e-05"/>
      <mass value="0.696"/>
      <inertia ixx="0.000469246" ixy="9.409e-06" ixz="3.42e-07" iyy="0.00080749" iyz="-4.66e-07" izz="0.000552929"/>
    </inertial>
  </link>
  <joint name="RL_hip_fixed" type="fixed">
    <origin rpy="0 0 0" xyz="0 0.081 0"/>
    <parent link="RL_hip"/>
    <child link="RL_thigh_shoulder"/>
  </joint>
  <!-- this link is only for collision -->
  <link name="RL_thigh_shoulder">
    <!-- <collision>
      <origin rpy="1.57079632679 0 0" xyz="0 0 0"/>
      <geometry>
        <cylinder length="0.032" radius="0.041"/>
      </geometry>
    </collision> -->
  </link>
  <joint name="RL_thigh_joint" type="revolute">
    <origin rpy="0 0 0" xyz="0 0.08505 0"/>
    <parent link="RL_hip"/>
    <child link="RL_thigh"/>
    <axis xyz="0 1 0"/>
    <dynamics damping="0" friction="0"/>
    <limit effort="55" lower="-1.0471975512" upper="4.18879020479" velocity="28.6"/>
  </joint>
  <link name="RL_thigh">
    <visual>
      <origin rpy="0 0 0" xyz="0 0 0"/>
      <geometry>
        <mesh filename="../meshes/thigh.dae" scale="1 1 1"/>
      </geometry>
      <material name="orange"/>
    </visual>
    <collision>
      <origin rpy="0 1.57079632679 0" xyz="0 0 -0.1"/>
      <geometry>
        <box size="0.2 0.0245 0.034"/>
      </geometry>
    </collision>
    <inertial>
      <origin rpy="0 0 0" xyz="-0.003237 -0.022327 -0.027326"/>
      <mass value="1.013"/>
      <inertia ixx="0.005529065" ixy="4.825e-06" ixz="0.000343869" iyy="0.005139339" iyz="2.2448e-05" izz="0.001367788"/>
    </inertial>
  </link>
  <joint name="RL_calf_joint" type="revolute">
    <origin rpy="0 0 0" xyz="0 0 -0.2"/>
    <parent link="RL_thigh"/>
    <child link="RL_calf"/>
    <axis xyz="0 1 0"/>
    <dynamics damping="0" friction="0"/>
    <limit effort="55" lower="-2.69653369433" upper="-0.916297857297" velocity="28.6"/>
  </joint>
  <link name="RL_calf">
    <visual>
      <origin rpy="0 0 0" xyz="0 0 0"/>
      <geometry>
        <mesh filename="../meshes/calf.dae" scale="1 1 1"/>
      </geometry>
      <material name="orange"/>
    </visual>
    <collision>
      <origin rpy="0 1.57079632679 0" xyz="0 0 -0.1"/>
      <geometry>
        <box size="0.2 0.016 0.016"/>
      </geometry>
    </collision>
    <inertial>
      <origin rpy="0 0 0" xyz="0.006435 0.0 -0.107388"/>
      <mass value="0.166"/>
      <inertia ixx="0.002997972" ixy="0.0" ixz="-0.000141163" iyy="0.003014022" iyz="0.0" izz="3.2426e-05"/>
    </inertial>
  </link>
  <joint name="RL_foot_fixed" type="fixed" dont_collapse="true">
    <origin rpy="0 0 0" xyz="0 0 -0.2"/>
    <parent link="RL_calf"/>
    <child link="RL_foot"/>
  </joint>
  <link name="RL_foot">
    <visual>
      <origin rpy="0 0 0" xyz="0 0 0"/>
      <geometry>
        <sphere radius="0.01"/>
      </geometry>
      <material name="orange"/>
    </visual>
    <collision>
      <origin rpy="0 0 0" xyz="0 0 0"/>
      <geometry>
        <sphere radius="0.02"/>
      </geometry>
    </collision>
    <inertial>
      <mass value="0.06"/>
      <inertia ixx="9.6e-06" ixy="0.0" ixz="0.0" iyy="9.6e-06" iyz="0.0" izz="9.6e-06"/>
    </inertial>
  </link>

  <!-- APPEND TAIL URDF -->

  <link name="base_link">
    <inertial>
      <origin xyz="0.00368134633125201 0.00383986483493379 0.0260332873989196" rpy="0 0 0" />
      <mass value="0.555746166352667" />
      <inertia ixx="0.000564569531443187" ixy="-2.1594155115282E-05" ixz="-1.97006796795357E-06" iyy="0.000443501475714245" iyz="-2.02970909322008E-05" izz="0.000973839619785963" />
    </inertial>
    <visual>
      <origin xyz="0 0 0" rpy="0 0 0" />
      <geometry>
        <mesh filename="../meshes/base_link.obj" />
      </geometry>
      <material name="">
        <!-- <color rgba="0 0 0 0.8" /> -->
      </material>
    </visual>
    <collision>
      <origin xyz="0 0 0" rpy="0 0 0" />
      <geometry>
        <mesh filename="../meshes/base_link.obj" />
      </geometry>
    </collision>
  </link>
  <joint name="tail_mount" type="fixed">
    <origin rpy="0 0 -1.5708" xyz="-0.045 0 0.055"/>
    <parent link="trunk"/>
    <child link="base_link"/>
  </joint>
  <link name="motor_bracket">
    <inertial>
      <origin xyz="-2.88836212974676E-17 0.0049442016257755 -0.000718517500351113" rpy="0 0 0" />
      <mass value="0.0361562335715199" />
      <inertia ixx="2.53367831062421E-05" ixy="-8.748397385993E-22" ixz="6.79410470129006E-12" iyy="3.34621730544853E-05" iyz="3.39270759533818E-23" izz="8.51428709634465E-06" />
    </inertial>
    <visual>
      <origin xyz="0 0 0" rpy="0 0 0" />
      <geometry>
        <mesh filename="../meshes/motor_bracket.obj" />
      </geometry>
      <material name="">
        <!-- <color rgba="0 0 0 0.8" /> -->
      </material>
    </visual>
    <collision>
      <origin xyz="0 0 0" rpy="0 0 0" />
      <geometry>
        <mesh filename="../meshes/motor_bracket.obj" />
      </geometry>
    </collision>
  </link>
  <joint name="tail_shoulder_yaw_joint" type="revolute">
    <origin xyz="0 -0.0250000074045035 0.0704999736568643" rpy="1.5707963267949 0 0" />
    <parent link="base_link" />
    <child link="motor_bracket" />
    <axis xyz="0 1 0" />
    <limit
      lower="-3.1416"
      upper="3.1416"
      effort="0"
      velocity="0" />
  </joint>
  <link name="link_1_1">
    <inertial>
      <origin xyz="0.0905473652790637 0.000711260512443836 0.0132318529133212" rpy="0 0 0" />
      <mass value="0.10522422497625" />
      <inertia ixx="4.9170948109236E-05" ixy="3.44838343166424E-07" ixz="-6.33912476285388E-06" iyy="0.000566745463767469" iyz="1.86818652106595E-09" izz="0.000611643830976391" />
    </inertial>
    <visual>
      <origin xyz="0 0 0" rpy="0 0 0" />
      <geometry>
        <mesh filename="../meshes/link_1_1.obj" />
      </geometry>
      <material name="">
        <!-- <color rgba="0 0 0 0.8" /> -->
      </material>
    </visual>
    <collision>
      <origin xyz="0 0 0" rpy="0 0 0" />
      <geometry>
        <mesh filename="../meshes/link_1_1.obj" />
      </geometry>
    </collision>
  </link>
  <joint name="tail_shoulder_pitch_joint" type="revolute">
    <origin xyz="0 0.052 0" rpy="-1.5708 0 1.5708" />
    <parent link="motor_bracket" />
    <child link="link_1_1" />
    <axis xyz="0 0 -1" />
    <limit
      lower="-1.5708"
      upper="1.5708"
      effort="0"
      velocity="0" />
  </joint>
  <link
    name="link_2">
    <inertial>
      <origin xyz="-6.96295926472246E-09 -0.080424811499244 -5.62814089838616E-05" rpy="0 0 0" />
      <mass value="0.0763189346847985" />
      <inertia ixx="0.000193794609294917" ixy="-4.46258884884084E-12" ixz="1.575349661543E-11" iyy="1.19346850461047E-05" iyz="-3.84316854395656E-07" izz="0.000200914946760075" />
    </inertial>
    <visual>
      <origin xyz="0 0 0" rpy="0 0 0" />
      <geometry>
        <mesh filename="../meshes/link_2.obj" />
      </geometry>
      <material name="">
        <!-- <color rgba="0 0 0 0.8" /> -->
      </material>
    </visual>
    <collision>
      <origin xyz="0 0 0" rpy="0 0 0" />
      <geometry>
        <mesh filename="../meshes/link_2.obj" />
      </geometry>
    </collision>
  </link>
  <joint
    name="tail_elbow_joint"
    type="revolute">
    <origin xyz="0.22094 0.00071851 0" rpy="0 0 0" />
    <parent link="link_1_1" />
    <child link="link_2" />
    <axis xyz="0 0 1" />
    <limit
      lower="0"
      upper="1.5708"
      effort="0"
      velocity="0" />
  </joint>
  <link name="gripper">
    <inertial>
      <origin xyz="0.0573436204221779 -0.0395765636354563 -0.00060674366183752" rpy="0 0 0" />
      <mass value="0.203470349399239" />
      <inertia ixx="5.65426795005758E-05" ixy="-3.99750990342292E-05"ixz="1.78408717761704E-07" iyy="0.000230730550351754" iyz="-2.27266291884127E-07" izz="0.00026423414761495" />
    </inertial>
    <visual>
      <origin xyz="0 0 0" rpy="0 0 0" />
      <geometry>
        <mesh filename="../meshes/gripper.obj" />
      </geometry>
      <material name="">
        <!-- <color rgba="0 0 0 0.8" /> -->
      </material>
    </visual>
    <collision>
      <origin xyz="0 0 0" rpy="0 0 0" />
      <geometry>
        <mesh filename="../meshes/gripper.obj" />
      </geometry>
    </collision>
  </link>
  <joint name="gripper_fixed_joint" type="fixed">
    <origin xyz="-0.0444441987014288 -0.336718519125746 0" rpy="3.14159265358979 0 -1.57079632679503" />
    <parent link="link_2" />
    <child link="gripper" />
    <axis xyz="0 0 0" />
  </joint>
  <link name="link_1_2">
    <inertial>
      <origin xyz="-0.0314199921617841 -0.00071837333398065 0.00385190919585071" rpy="0 0 0" />
      <mass value="0.0948432334787272" />
      <inertia ixx="4.75228867726751E-05" ixy="9.01698567690483E-10" ixz="-9.0340126283445E-06" iyy="0.000462256039513398" iyz="1.93962855038886E-11" izz="0.000505534714703268" />
    </inertial>
    <visual>
      <origin xyz="0 0 0" rpy="0 0 0" />
      <geometry>
        <mesh filename="../meshes/link_1_2.obj" />
      </geometry>
      <material
        name="">
        <!-- <color rgba="0 0 0 0.8" /> -->
      </material>
    </visual>
    <collision>
      <origin xyz="0 0 0" rpy="0 0 0" />
      <geometry>
        <mesh filename="../meshes/link_1_2.obj" />
      </geometry>
    </collision>
  </link>
  <joint name="link_1_2" type="fixed">
    <origin xyz="0.131599993038923 0 -0.00899999748365095" rpy="-3.14159265358979 0 0" />
    <parent link="link_1_1" />
    <child link="link_1_2" />
    <axis xyz="0 0 0" />
  </joint>
  <link name="motor_2">
    <inertial>
      <origin xyz="0.000415160647521215 -0.00599711221017367 0.000853420896040624" rpy="0 0 0" />
      <mass value="0.293750772256237" />
      <inertia ixx="0.000131437212880793" ixy="-1.45875965303565E-07" ixz="-5.95974642870492E-06" iyy="0.000249003244796522" iyz="8.86875080429919E-08" izz="0.000138018696135985" />
    </inertial>
    <visual>
      <origin xyz="0 0 0" rpy="0 0 0" />
      <geometry>
        <mesh filename="../meshes/motor_2.obj" />
      </geometry>
      <material name="">
        <!-- <color rgba="0 0 0 0.8" /> -->
      </material>
    </visual>
    <collision>
      <origin xyz="0 0 0" rpy="0 0 0" />
      <geometry>
        <mesh filename="../meshes/motor_2.obj" />
      </geometry>
    </collision>
  </link>
  <joint name="motor_2" type="fixed">
    <origin xyz="0.0642499999999967 0.0520000037921046 0" rpy="-3.14159265358978 1.04719755119654 1.57079632679491" />
    <parent link="motor_bracket" />
    <child link="motor_2" />
    <axis xyz="0 0 0" />
  </joint>
  <link name="motor_3">
    <inertial>
      <origin xyz="0.0010594901135863 -0.005997111629483 -0.000262627762671955" rpy="0 0 0" />
      <mass value="0.293750772256237" />
      <inertia ixx="0.000131437217831497" ixy="-1.45906394621066E-07" ixz="-5.95975140378827E-06" iyy="0.000249003244796523" iyz="8.86902171652028E-08" izz="0.000138018691185278" />
    </inertial>
    <visual>
      <origin xyz="0 0 0" rpy="0 0 0" />
      <geometry>
        <mesh filename="../meshes/motor_3.obj" />
      </geometry>
      <material name="">
        <!-- <color rgba="0 0 0 0.8" /> -->
      </material>
    </visual>
    <collision>
      <origin xyz="0 0 0" rpy="0 0 0" />
      <geometry>
        <mesh filename="../meshes/motor_3.obj" />
      </geometry>
    </collision>
  </link>
  <joint name="motor_3" type="fixed">
    <origin xyz="-0.0642499999999978 0.0520000040598411 0" rpy="3.14159265358978 1.04719755119673 -1.5707963267949" />
    <parent link="motor_bracket" />
    <child link="motor_3" />
    <axis xyz="0 0 0" />
  </joint>

    <link name="battery_asm">
    <inertial>
      <origin xyz="0.0055402336368483 0.0549433712373477 3.85298046699102E-07" rpy="0 0 0" />
      <mass value="0.792464358247873" />
      <inertia ixx="0.000599464799357989" ixy="4.74333059445186E-06" ixz="3.08452719159931E-08" iyy="0.00273213202135635" iyz="-1.1921064859431E-09" izz="0.00251553733007407" />
    </inertial>
    <visual>
      <origin xyz="0 0 0" rpy="0 0 0" />
      <geometry>
        <mesh filename="../meshes/battery_asm.obj" />
      </geometry>
      <material name="">
        <!-- <color rgba="0.792156862745098 0.819607843137255 0.933333333333333 1" /> -->
      </material>
    </visual> 
    <collision>
      <origin xyz="0 0 0" rpy="0 0 0" />
      <geometry>
        <mesh filename="../meshes/battery_asm.obj" />
      </geometry>
    </collision>
  </link>
  <joint name="battery_mount" type="fixed">
    <origin rpy="0 0 3.14159" xyz="0.20 0 0.055"/>
    <parent link="trunk"/>
    <child link="battery_asm"/>
  </joint>
</robot>

